Workbook
Name ar: #REF!
Name cl: #REF!
Name comp: #REF!
Name compagnies_retenues: #REF!
Name comparison: #REF!
Name countries: #REF!
Name COUNTRYLU: 'Country Code LU'!$A$1:$D$250
Name cov: #REF!
Name customers: #REF!
Name format: #REF!
Name labelling: #REF!
Name lpuk: #REF!
Name offerchosen: #REF!
Name option: #REF!
Name rmtariff: #REF!
Name ServiceLevel: [1]Data!$A$2:$A$3
Name type: #REF!
Name valid_from: #REF!
Name valid_from: #REF!
Name valid_from: #REF!
Name valid_from: #REF!
Name valid_from: #REF!
Name value: #REF!
Name vs: #REF!
Name weight: #REF!

Sheet Priority Manifest
B1: Priority
G2: Preparation Level (Please enter X) | K2: Franking Level (Please enter X)
B3: Asendia UK Business Mail | G3: Fully Prepared | H3: x | I3: Part Prepared | K3: Full PPI | L3: x | M3: Part PPI
B4: Valid from 1st January 2025 | G4: Note: Surcharges will apply for any Part Prepared/Part Franked volumes received
B6: Customer Name | D6: Citipost Ltd | G6: Customer Ref | L6: Shipment Date
B7: Authorisation # | G7: Quotation # | L7: Number of bags | N7: 1
D9: Letters | G9: Letters | I9: Flats | L9: Flats | N9: Packets | Q9: Packets
C10: PRIORITY | H10: PRIORITY | M10: PRIORITY
C11: LETTERS | H11: BOXABLE/FLAT | M11: NON-BOXABLE/PACKET
C12: Weight Band | D12: Route | E12: Total Items | F12: Total Weight | H12: Weight Band | I12: Route | J12: Total Items | K12: Total Weight | M12: Weight Band | N12: Route | O12: Total Items | P12: Total Weight | Y12: Master Country List
A13: AT | B13: Austria | C13: 0-100g | D13: Swiss Post | H13: 0-2000g | I13: Swiss Post | M13: 0-2000g | N13: La Poste | T13: AT | V13: AT | Y13: Austria | AB13: =IF(Y13=B13,"TRUE","FALSE") -> TRUE
A14: BE | B14: Belgium | C14: 0-100g | D14: Swiss Post | H14: 0-2000g | I14: La Poste | M14: 0-2000g | N14: La Poste | T14: BE | V14: BE | Y14: Belgium | AB14: =IF(Y14=B14,"TRUE","FALSE") -> TRUE
A15: HR | B15: Croatia | C15: 0-100g | D15: La Poste | H15: 0-2000g | I15: La Poste | M15: 0-2000g | N15: La Poste | T15: HR | V15: HR | Y15: Croatia | AB15: =IF(Y15=B15,"TRUE","FALSE") -> TRUE
A16: CZ | B16: Czech Republic | C16: 0-100g | D16: La Poste | H16: 0-2000g | I16: La Poste | M16: 0-2000g | N16: La Poste | T16: CZ | V16: CZ | Y16: Czech Republic | AB16: =IF(Y16=B16,"TRUE","FALSE") -> TRUE
A17: DK | B17: Denmark | C17: 0-100g | D17: La Poste | H17: 0-500g | I17: La Poste | M17: 0-2000g | N17: La Poste | T17: DK | V17: DK | Y17: Denmark | AB17: =IF(Y17=B17,"TRUE","FALSE") -> TRUE
A18: EE | B18: Estonia | C18: 0-100g | D18: La Poste | H18: 0-2000g | I18: La Poste | M18: 0-2000g | N18: La Poste | T18: EE | V18: EE | Y18: Estonia | AB18: =IF(Y18=B18,"TRUE","FALSE") -> TRUE
A19: FI | B19: Finland | C19: 0-100g | D19: La Poste | H19: 0-2000g | I19: La Poste | M19: 0-2000g | N19: La Poste | T19: FI | V19: FI | Y19: Finland | AB19: =IF(Y19=B19,"TRUE","FALSE") -> TRUE
A20: FR | B20: France | C20: 0-100g | D20: La Poste | H20: 0-2000g | I20: La Poste | M20: 0-2000g | N20: La Poste | T20: FR | V20: FR | Y20: France | AB20: =IF(Y20=B20,"TRUE","FALSE") -> TRUE
A21: DE | B21: Germany | C21: 0-100g | D21: Swiss Post | H21: 0-2000g | I21: La Poste | M21: 0-2000g | N21: La Poste | T21: DE | V21: DE | Y21: Germany | AB21: =IF(Y21=B21,"TRUE","FALSE") -> TRUE
A22: GR | B22: Greece | C22: 0-100g | D22: La Poste | H22: 0-2000g | I22: La Poste | M22: 0-2000g | N22: La Poste | T22: GR | V22: GR | Y22: Greece | AB22: =IF(Y22=B22,"TRUE","FALSE") -> TRUE
A23: HU | B23: Hungary | C23: 0-100g | D23: La Poste | H23: 0-2000g | I23: La Poste | M23: 0-2000g | N23: La Poste | T23: HU | V23: HU | Y23: Hungary | AB23: =IF(Y23=B23,"TRUE","FALSE") -> TRUE
A24: IS | B24: Iceland | C24: 0-100g | D24: Swiss Post | H24: 0-2000g | I24: La Poste | M24: 0-5000g | N24: La Poste | T24: IS | V24: IS | Y24: Iceland | AB24: =IF(Y24=B24,"TRUE","FALSE") -> TRUE
... A39: CH | B39: Switzerland | C39: 0-100g | D39: Swiss Post | H39: 0-2000g | I39: Swiss Post | M39: 0-5000g | N39: Swiss Post | T39: CH | V39: CH | Y39: Switzerland | AB39: =IF(Y39=B39,"TRUE","FALSE") -> TRUE
A40: CH
B41: UK (1st Class) | C41: 0-100g | D41: Royal Mail | H41: 0-500g | I41: Royal Mail | M41: 0-2000g | N41: Royal Mail | Y41: UK | AB41: =IF(Y41=B41,"TRUE","FALSE") -> FALSE
B44: Work Required | C44: Sortation | D44: Franking | E44: Other (state) | M44: EUROPE + ROW | O44: Item # | P44: Weight
B45: Office Check | M45: TOTAL | O45: =SUM(E13:E41,J13:J41,O13:O41,E60:E71,J60:J71,O60:O71,E76:E98,O76:O99,E110:E152,O110:O146,E164:E196,O164:O189) -> 0 | P45: =SUM(F13:F41,K13:K41,P13:P41,F60:F71,K60:K71,P60:P71,F76:F98,P76:P99,F110:F152,P110:P146,F164:F196,P164:P189) -> 0
B51: Asendia UK Business Mail
B52: =B4 -> Valid from 1st January 2025
B54: Customer Name | D54: =IF($D$6=0,"",$D$6) -> Citipost Ltd | G54: Authorisation # | I54: =IF($D$7=0,"",$D$7) | L54: Shipment Date | N54: =IF($N$6=0,"",$N$6)
D56: Letters | G56: Letters | I56: Flats | L56: Flats | N56: Packets | Q56: Packets
C57: PRIORITY | H57: PRIORITY | M57: PRIORITY
C58: LETTERS | H58: FLAT | M58: PACKET
C59: Weight Band | D59: Route | E59: Total Items | F59: Total Weight | H59: Weight Band | I59: Route | J59: Total Items | K59: Total Weight | M59: Weight Band | N59: Route | O59: Total Items | P59: Total Weight
A60: AU | B60: Australia | C60: 0-100g | D60: La Poste | H60: 0-500g | I60: La Poste | M60: 0-2000g | N60: La Poste | T60: AU | V60: AU | Y60: Australia | AB60: =IF(Y60=B60,"TRUE","FALSE") -> TRUE
A61: CA | B61: Canada | C61: 0-100g | D61: Swiss Post | H61: 0-500g | I61: Swiss Post | M61: 0-2000g | N61: Swiss Post | T61: CA | V61: CA | Y61: Canada | AB61: =IF(Y61=B61,"TRUE","FALSE") -> TRUE
B62: China | C62: 0-100g | D62: La Poste | H62: 0-500g | I62: La Poste | M62: 0-5000g | N62: La Poste | T62: CN | V62: CN | Y62: China | AB62: =IF(Y62=B62,"TRUE","FALSE") -> TRUE
B63: Israel | C63: 0-100g | D63: La Poste | H63: 0-500g | I63: La Poste | M63: 0-5000g | N63: La Poste | T63: IL | V63: IL | Y63: Israel | AB63: =IF(Y63=B63,"TRUE","FALSE") -> TRUE
B64: Japan | C64: 0-100g | D64: Swiss Post | H64: 0-500g | I64: Swiss Post | M64: 0-5000g | N64: Swiss Post | T64: JP | V64: JP | Y64: Japan | AB64: =IF(Y64=B64,"TRUE","FALSE") -> TRUE
B65: Malta | C65: 0-100g | D65: Swiss Post | H65: 0-500g | I65: La Poste | M65: 0-5000g | N65: La Poste
...

Sheet Non-Priority Manifest
B1: Non-Priority
G2: Preparation Level (Please enter X) | K2: Franking Level (Please enter X)
B3: Asendia UK Business Mail | G3: Fully Prepared | H3: x | I3: Part Prepared | K3: Full PPI | L3: x | M3: Part PPI
B4: ='Priority Manifest'!$B$4 -> Valid from 1st January 2025 | G4: Note: Surcharges will apply for any Part Prepared/Part Franked volumes received
B6: Customer Name | D6: Citipost Limited | G6: Customer Ref | L6: Shipment Date
B7: Authorisation # | G7: Quotation # | L7: Number of bags
D9: Letters | G9: Letters | I9: Flats | L9: Flats | N9: Packets | Q9: Packets
C10: NON-PRIORITY | H10: NON-PRIORITY | M10: NON-PRIORITY
C11: LETTERS | H11: BOXABLE/FLAT | M11: NON-BOXABLE/PACKET
C12: Weight Band | D12: Route | E12: Total Items | F12: Total Weight | H12: Weight Band | I12: Route | J12: Total Items | K12: Total Weight | M12: Weight Band | N12: Route | O12: Total Items | P12: Total Weight | Y12: Master Country List
A13: AT | B13: Austria | C13: 0-100g | D13: La Poste | H13: 0-2000g | I13: Swiss Post | M13: 0-2000g | N13: La Poste | T13: AT | V13: AT | Y13: Austria | AB13: =IF(Y13=B13,"TRUE","FALSE") -> TRUE
A14: BE | B14: Belgium | C14: 0-100g | D14: Swiss Post | H14: 0-2000g | I14: Swiss Post | M14: 0-2000g | N14: Swiss Post | T14: BE | V14: BE | Y14: Belgium | AB14: =IF(Y14=B14,"TRUE","FALSE") -> TRUE
A15: HR | B15: Croatia | C15: 0-100g | D15: La Poste | H15: 0-2000g | I15: La Poste | M15: 0-2000g | N15: La Poste | T15: HR | V15: HR | Y15: Croatia | AB15: =IF(Y15=B15,"TRUE","FALSE") -> TRUE
A16: CZ | B16: Czech Republic | C16: 0-100g | D16: La Poste | H16: 0-2000g | I16: La Poste | M16: 0-2000g | N16: La Poste | T16: CZ | V16: CZ | Y16: Czech Republic | AB16: =IF(Y16=B16,"TRUE","FALSE") -> TRUE
A17: DK | B17: Denmark | C17: 0-100g | D17: La Poste | H17: 0-500g | I17: La Poste | M17: 0-2000g | N17: La Poste | T17: DK | V17: DK | Y17: Denmark | AB17: =IF(Y17=B17,"TRUE","FALSE") -> TRUE
A18: EE | B18: Estonia | C18: 0-100g | D18: La Poste | H18: 0-2000g | I18: La Poste | M18: 0-2000g | N18: La Poste | T18: EE | V18: EE | Y18: Estonia | AB18: =IF(Y18=B18,"TRUE","FALSE") -> TRUE
A19: FI | B19: Finland | C19: 0-100g | D19: La Poste | H19: 0-2000g | I19: La Poste | M19: 0-2000g | N19: La Poste | T19: FI | V19: FI | Y19: Finland | AB19: =IF(Y19=B19,"TRUE","FALSE") -> TRUE
A20: FR | B20: France | C20: 0-100g | D20: La Poste | H20: 0-2000g | I20: La Poste | M20: 0-2000g | N20: La Poste | T20: FR | V20: FR | Y20: France | AB20: =IF(Y20=B20,"TRUE","FALSE") -> TRUE
A21: DE | B21: Germany | C21: 0-100g | D21: Swiss Post | H21: 0-2000g | I21: Swiss Post | M21: 0-2000g | N21: La Poste | T21: DE | V21: DE | Y21: Germany | AB21: =IF(Y21=B21,"TRUE","FALSE") -> TRUE
A22: GR | B22: Greece | C22: 0-100g | D22: La Poste | H22: 0-2000g | I22: La Poste | M22: 0-2000g | N22: La Poste | T22: GR | V22: GR | Y22: Greece | AB22: =IF(Y22=B22,"TRUE","FALSE") -> TRUE
A23: HU | B23: Hungary | C23: 0-100g | D23: La Poste | H23: 0-2000g | I23: La Poste | M23: 0-2000g | N23: La Poste | T23: HU | V23: HU | Y23: Hungary | AB23: =IF(Y23=B23,"TRUE","FALSE") -> TRUE
A24: IS | B24: Iceland | C24: 0-100g | D24: La Poste | H24: 0-2000g | I24: La Poste | M24: 0-5000g | N24: La Poste | T24: IS | V24: IS | Y24: Iceland | AB24: =IF(Y24=B24,"TRUE","FALSE") -> TRUE
... A39: CH | B39: Switzerland | C39: 0-100g | D39: Swiss Post | H39: 0-2000g | I39: Swiss Post | M39: 0-5000g | N39: Swiss Post | T39: CH | V39: CH | Y39: Switzerland | AB39: =IF(Y39=B39,"TRUE","FALSE") -> TRUE
A40: CH
B41: UK (1st Class) | C41: 0-100g | D41: Royal Mail | H41: 0-500g | I41: Royal Mail | M41: 0-2000g | N41: Royal Mail | Y41: UK | AB41: =IF(Y41=B41,"TRUE","FALSE") -> FALSE
B44: Work Required | C44: Sortation | D44: Franking | E44: Other (state) | M44: EUROPE + ROW | O44: Item # | P44: Weight
B45: Office Check | M45: TOTAL | O45: =SUM(E13:E41,J13:J41,O13:O41,E60:E71,J60:J71,O60:O71,E76:E98,O76:O99,E110:E152,O110:O146,E163:E195,O163:O188) -> 0 | P45: =SUM(F13:F41,K13:K41,P13:P41,F60:F71,K60:K71,P60:P71,F76:F98,P76:P99,F110:F152,P110:P146,F163:F195,P163:P188) -> 0
B51: Asendia UK Business Mail
B52: =B4 -> Valid from 1st January 2025
B54: Customer Name | D54: =IF($D$6=0,"",$D$6) -> Citipost Limited | G54: Authorisation # | I54: =IF($D$7=0,"",$D$7) | L54: Shipment Date | N54: =IF($N$6=0,"",$N$6)
D56: Letters | G56: Letters | I56: Flats | L56: Flats | N56: Packets | Q56: Packets
C57: NON-PRIORITY | H57: NON-PRIORITY | M57: NON-PRIORITY
C58: LETTERS | H58: FLAT | M58: PACKET
C59: Weight Band | D59: Route | E59: Total Items | F59: Total Weight | H59: Weight Band | I59: Route | J59: Total Items | K59: Total Weight | M59: Weight Band | N59: Route | O59: Total Items | P59: Total Weight
A60: AU | B60: Australia | C60: 0-100g | D60: La Poste | H60: 0-500g | I60: La Poste | M60: 0-2000g | N60: La Poste | T60: AU | V60: AU | Y60: Australia | AB60: =IF(Y60=B60,"TRUE","FALSE") -> TRUE
A61: CA | B61: Canada | C61: 0-100g | D61: Swiss Post | H61: 0-500g | I61: Swiss Post | M61: 0-2000g | N61: Swiss Post | T61: CA | V61: CA | Y61: Canada | AB61: =IF(Y61=B61,"TRUE","FALSE") -> TRUE
B62: China | C62: 0-100g | D62: La Poste | H62: 0-500g | I62: La Poste | M62: 0-5000g | N62: La Poste | T62: CN | V62: CN | Y62: China | AB62: =IF(Y62=B62,"TRUE","FALSE") -> TRUE
B63: Israel | C63: 0-100g | D63: La Poste | H63: 0-500g | I63: La Poste | M63: 0-5000g | N63: La Poste | T63: IL | V63: IL | Y63: Israel | AB63: =IF(Y63=B63,"TRUE","FALSE") -> TRUE
B64: Japan | C64: 0-100g | D64: Swiss Post | H64: 0-500g | I64: Swiss Post | M64: 0-5000g | N64: Swiss Post | T64: JP | V64: JP | Y64: Japan | AB64: =IF(Y64=B64,"TRUE","FALSE") -> TRUE
B65: Malta | C65: 0-100g | D65: Swiss Post | H65: 0-500g | I65: La Poste | M65: 0-5000g | N65: La Poste
...

Sheet M-Bag Priority Manifest
B1: Priority
G2: Preparation Level (Please enter X) | K2: Franking Level (Please enter X)
B3: Asendia UK Business Mail | G3: Fully Prepared | H3: x | I3: Part Prepared | K3: Full PPI | M3: Part PPI
B4: ='Priority Manifest'!B4 -> Valid from 1st January 2025 | G4: Note: Surcharges will apply for any Part Prepared/Part Franked volumes received
B6: Customer Name | G6: Customer Ref | L6: Shipment Date
B7: Authorisation # | G7: Quotation # | L7: Number of bags
C9: Under 5kg | D9: Under 5kg | F9: Under 5kg | G9: Over 5kg | H9: Over 5kg | J9: Over 5kg
C10: PRIORITY | G10: PRIORITY
C11: 2-5 KG | G11: 5-25 KG
C12: Route | D12: Total Items | E12: Total Weight | G12: Route | H12: Total Items | I12: Total Weight | Y12: Master Country List
A13: IT | B13: Italy | C13: Swiss Post | G13: Swiss Post | T13: IT | U13: IT | Y13: Italy | AB13: =IF(Y13=B13,"TRUE","FALSE") -> TRUE
A14: LV | B14: Latvia | C14: Swiss Post | G14: Swiss Post | T14: LV | U14: LV | Y14: Latvia | AB14: =IF(Y14=B14,"TRUE","FALSE") -> TRUE
A15: PT | B15: Portugal | C15: Swiss Post | G15: Swiss Post | T15: PT | U15: PT | Y15: Portugal | AB15: =IF(Y15=B15,"TRUE","FALSE") -> TRUE
A16: RO | B16: Romania | C16: Swiss Post | G16: Swiss Post | T16: RO | U16: RO | Y16: Romania | AB16: =IF(Y16=B16,"TRUE","FALSE") -> TRUE
A17: SK | B17: Slovakia | C17: Swiss Post | G17: Swiss Post | T17: SK | U17: SK | Y17: Slovakia | AB17: =IF(Y17=B17,"TRUE","FALSE") -> TRUE
A18: CH | B18: Switzerland | C18: Swiss Post | G18: Swiss Post | T18: CH | U18: CH | Y18: Switzerland | AB18: =IF(Y18=B18,"TRUE","FALSE") -> TRUE
B21: UK | C21: Royal Mail | G21: Royal Mail | Y21: UK | AB21: =IF(Y21=B21,"TRUE","FALSE") -> TRUE
B24: Work Required | C24: Sortation | D24: Franking | E24: Other (state) | M24: EUROPE + ROW | O24: Item # | P24: Weight
B25: Office Check | M25: TOTAL | O25: =SUM(D13:D21,H13:H21,D37:D40,H37:H40,D41:D43,H41:H43,D44:D46,H44:H46,D47:D50,H47:H50,D51:D54,H51:H54) -> 0 | P25: =SUM(E13:E21,I13:I21,E37:E40,I37:I40,E41:E43,I41:I43,E44:E46,I44:I46,E47:E50,I47:I50,E51:E54,I51:I54) -> 0
B29: Asendia UK Business Mail
B30: =$B$4 -> Valid from 1st January 2025
B32: Customer Name | D32: =IF($D$6=0,"",$D$6) | G32: Authorisation # | I32: =IF($D$7=0,"",$D$7) | L32: Shipment Date | N32: =IF($N$6=0,"",$N$6)
F33: Under 5kg | J33: Over 5kg
C34: PRIORITY | G34: PRIORITY
C35: 2-5 KG | G35: 5-25 KG
C36: Route | D36: Total Items | E36: Total Weight | G36: Route | H36: Total Items | I36: Total Weight
B37: Azerbaijan | C37: Swiss Post | G37: Swiss Post | T37: AZ | U37: ZZZZ | Y37: Azerbaijan | AB37: =IF(Y37=B37,"TRUE","FALSE") -> TRUE
B38: Bosnia & Herzegovina | C38: Swiss Post | G38: Swiss Post | T38: BR | U38: ZZZZ | Y38: Bosnia & Herzegovina | AB38: =IF(Y38=B38,"TRUE","FALSE") -> TRUE
B39: Cambodia | C39: Swiss Post | G39: Swiss Post | T39: KY | U39: ZZZZ | Y39: Cambodia | AB39: =IF(Y39=B39,"TRUE","FALSE") -> TRUE
B40: China | C40: Swiss Post | G40: Swiss Post | T40: KM | U40: =INDEX('Country Code LU'!$B$2:$B$250,MATCH($B40,'Country Code LU'!$A$2:$A$250,0)) -> CN | Y40: China | AB40: =IF(Y40=B40,"TRUE","FALSE") -> TRUE
B41: Costa Rica | C41: Swiss Post | G41: Swiss Post | T41: CR | U41: ZZZZ | Y41: Costa Rica | AB41: =IF(Y41=B41,"TRUE","FALSE") -> TRUE
B42: Egypt | C42: Swiss Post | G42: Swiss Post | T42: EG | U42: ZZZZ | Y42: Egypt | AB42: =IF(Y42=B42,"TRUE","FALSE") -> TRUE
B43: Ethiopia | C43: Swiss Post | G43: Swiss Post | T43: ET | U43: ZZZZ | Y43: Ethiopia | AB43: =IF(Y43=B43,"TRUE","FALSE") -> TRUE
B44: Israel | C44: Swiss Post | G44: Swiss Post | T44: JM | U44: =INDEX('Country Code LU'!$B$2:$B$250,MATCH($B44,'Country Code LU'!$A$2:$A$250,0)) -> IL | Y44: Israel | AB44: =IF(Y44=B44,"TRUE","FALSE") -> TRUE
B45: Kazakhstan | C45: Swiss Post | G45: Swiss Post | T45: KI | U45: ZZZZ | Y45: Kazakhstan | AB45: =IF(Y45=B45,"TRUE","FALSE") -> TRUE
B46: Macao | C46: Swiss Post | G46: Swiss Post | T46: MY | U46: ZZZZ | Y46: Macao | AB46: =IF(Y46=B46,"TRUE","FALSE") -> TRUE
B47: New Zealand | C47: Swiss Post | G47: Swiss Post | U47: =INDEX('Country Code LU'!$B$2:$B$250,MATCH($B47,'Country Code LU'!$A$2:$A$250,0)) -> NZ | Y47: New Zealand | AB47: =IF(Y47=B47,"TRUE","FALSE") -> TRUE
B48: Panama | C48: Swiss Post | G48: Swiss Post | T48: PW | U48: ZZZZ | Y48: Panama | AB48: =IF(Y48=B48,"TRUE","FALSE") -> TRUE
B49: Serbia | C49: Swiss Post | G49: Swiss Post | T49: SN | U49: ZZZZ | Y49: Serbia | AB49: =IF(Y49=B49,"TRUE","FALSE") -> TRUE
B50: Singapore | C50: Swiss Post | G50: Swiss Post | T50: SL | U50: =INDEX('Country Code LU'!$B$2:$B$250,MATCH($B50,'Country Code LU'!$A$2:$A$250,0)) -> SG | Y50: Singapore | AB50: =IF(Y50=B50,"TRUE","FALSE") -> TRUE
...

Sheet M-Bag Non-Priority Manifest
B1: Non-Priority
G2: Preparation Level (Please enter X) | K2: Franking Level (Please enter X)
B3: Asendia UK Business Mail | G3: Fully Prepared | H3: x | I3: Part Prepared | K3: Full PPI | M3: Part PPI
B4: ='Priority Manifest'!B4 -> Valid from 1st January 2025 | G4: Note: Surcharges will apply for any Part Prepared/Part Franked volumes received
B6: Customer Name | G6: Customer Ref | L6: Shipment Date
B7: Authorisation # | G7: Quotation # | L7: Number of bags
C9: Under 5kg | D9: Under 5kg | F9: Under 5kg | G9: Over 5kg | H9: Over 5kg | J9: Over 5kg
C10: NON-PRIORITY | G10: NON-PRIORITY
C11: 2-5 KG | G11: 5-25 KG
C12: Route | D12: Total Items | E12: Total Weight | G12: Route | H12: Total Items | I12: Total Weight | Y12: Master Country List
A13: IT | B13: Italy | C13: Swiss Post | G13: Swiss Post | T13: IT | U13: IT | Y13: Italy | AB13: =IF(Y13=B13,"TRUE","FALSE") -> TRUE
A14: LV | B14: Latvia | C14: Swiss Post | G14: Swiss Post | T14: LV | U14: LV | Y14: Latvia | AB14: =IF(Y14=B14,"TRUE","FALSE") -> TRUE
A15: PT | B15: Portugal | C15: Swiss Post | G15: Swiss Post | T15: PT | U15: PT | Y15: Portugal | AB15: =IF(Y15=B15,"TRUE","FALSE") -> TRUE
A16: RO | B16: Romania | C16: Swiss Post | G16: Swiss Post | T16: RO | U16: RO | Y16: Romania | AB16: =IF(Y16=B16,"TRUE","FALSE") -> TRUE
A17: SK | B17: Slovakia | C17: Swiss Post | G17: Swiss Post | T17: SK | U17: SK | Y17: Slovakia | AB17: =IF(Y17=B17,"TRUE","FALSE") -> TRUE
A18: CH | B18: Switzerland | C18: Swiss Post | G18: Swiss Post | T18: CH | U18: CH | Y18: Switzerland | AB18: =IF(Y18=B18,"TRUE","FALSE") -> TRUE
B21: UK | C21: Royal Mail | G21: Royal Mail | Y21: UK | AB21: =IF(Y21=B21,"TRUE","FALSE") -> TRUE
B24: Work Required | C24: Sortation | D24: Franking | E24: Other (state) | M24: EUROPE + ROW | O24: Item # | P24: Weight
B25: Office Check | M25: TOTAL | O25: =SUM(D13:D21,H13:H21,D37:D40,H37:H40,D41:D43,H41:H43,D44:D46,H44:H46,D47:D50,H47:H50,D51:D54,H51:H54) -> 0 | P25: =SUM(E13:E21,I13:I21,E37:E40,I37:I40,E41:E43,I41:I43,E44:E46,I44:I46,E47:E50,I47:I50,E51:E54,I51:I54) -> 0
B29: Asendia UK Business Mail
B30: =$B$4 -> Valid from 1st January 2025
B32: Customer Name | D32: =IF($D$6=0,"",$D$6) | G32: Authorisation # | I32: =IF($D$7=0,"",$D$7) | L32: Shipment Date | N32: =IF($N$6=0,"",$N$6)
F33: Under 5kg | J33: Over 5kg
C34: NON-PRIORITY | G34: NON-PRIORITY
C35: 2-5 KG | G35: 5-25 KG
C36: Route | D36: Total Items | E36: Total Weight | G36: Route | H36: Total Items | I36: Total Weight
B37: Azerbaijan | C37: Swiss Post | G37: Swiss Post | T37: AZ | U37: ZZZZ | Y37: Azerbaijan | AB37: =IF(Y37=B37,"TRUE","FALSE") -> TRUE
B38: Bosnia & Herzegovina | C38: Swiss Post | G38: Swiss Post | T38: BR | U38: ZZZZ | Y38: Bosnia & Herzegovina | AB38: =IF(Y38=B38,"TRUE","FALSE") -> TRUE
B39: Cambodia | C39: Swiss Post | G39: Swiss Post | T39: KY | U39: ZZZZ | Y39: Cambodia | AB39: =IF(Y39=B39,"TRUE","FALSE") -> TRUE
B40: China | C40: Swiss Post | G40: Swiss Post | T40: KM | U40: =INDEX('Country Code LU'!$B$2:$B$250,MATCH($B40,'Country Code LU'!$A$2:$A$250,0)) -> CN | Y40: China | AB40: =IF(Y40=B40,"TRUE","FALSE") -> TRUE
B41: Costa Rica | C41: Swiss Post | G41: Swiss Post | T41: CR | U41: ZZZZ | Y41: Costa Rica | AB41: =IF(Y41=B41,"TRUE","FALSE") -> TRUE
B42: Egypt | C42: Swiss Post | G42: Swiss Post | T42: EG | U42: ZZZZ | Y42: Egypt | AB42: =IF(Y42=B42,"TRUE","FALSE") -> TRUE
B43: Ethiopia | C43: Swiss Post | G43: Swiss Post | T43: ET | U43: ZZZZ | Y43: Ethiopia | AB43: =IF(Y43=B43,"TRUE","FALSE") -> TRUE
B44: Israel | C44: Swiss Post | G44: Swiss Post | T44: JM | U44: =INDEX('Country Code LU'!$B$2:$B$250,MATCH($B44,'Country Code LU'!$A$2:$A$250,0)) -> IL | Y44: Israel | AB44: =IF(Y44=B44,"TRUE","FALSE") -> TRUE
B45: Kazakhstan | C45: Swiss Post | G45: Swiss Post | T45: KI | U45: ZZZZ | Y45: Kazakhstan | AB45: =IF(Y45=B45,"TRUE","FALSE") -> TRUE
B46: Macao | C46: Swiss Post | G46: Swiss Post | T46: MY | U46: ZZZZ | Y46: Macao | AB46: =IF(Y46=B46,"TRUE","FALSE") -> TRUE
B47: New Zealand | C47: Swiss Post | G47: Swiss Post | U47: =INDEX('Country Code LU'!$B$2:$B$250,MATCH($B47,'Country Code LU'!$A$2:$A$250,0)) -> NZ | Y47: New Zealand | AB47: =IF(Y47=B47,"TRUE","FALSE") -> TRUE
B48: Panama | C48: Swiss Post | G48: Swiss Post | T48: PW | U48: ZZZZ | Y48: Panama | AB48: =IF(Y48=B48,"TRUE","FALSE") -> TRUE
B49: Serbia | C49: Swiss Post | G49: Swiss Post | T49: SN | U49: ZZZZ | Y49: Serbia | AB49: =IF(Y49=B49,"TRUE","FALSE") -> TRUE
B50: Singapore | C50: Swiss Post | G50: Swiss Post | T50: SL | U50: =INDEX('Country Code LU'!$B$2:$B$250,MATCH($B50,'Country Code LU'!$A$2:$A$250,0)) -> SG | Y50: Singapore | AB50: =IF(Y50=B50,"TRUE","FALSE") -> TRUE
...

Sheet Country Code LU
A1: Country | B1: Alpha-2 code | C1: Alpha-3 code | D1: Numeric
A2: Afghanistan | B2: AF | C2: AFG | D2: 4
A3: Albania | B3: AL | C3: ALB | D3: 8
A4: Algeria | B4: DZ | C4: DZA | D4: 12
A5: American Samoa | B5: AS | C5: ASM | D5: 16
A6: Andorra | B6: AD | C6: AND | D6: 20
A7: Angola | B7: AO | C7: AGO | D7: 24
A8: Anguilla | B8: AI | C8: AIA | D8: 660
A9: Antarctica | B9: AQ | C9: ATA | D9: 10
A10: Antigua and Barbuda | B10: AG | C10: ATG | D10: 28
A11: Argentina | B11: AR | C11: ARG | D11: 32
A12: Armenia | B12: AM | C12: ARM | D12: 51
A13: Aruba | B13: AW | C13: ABW | D13: 533
... A250: Åland Islands | B250: AX | C250: ALA | D250: 248
