Workbook

Sheet Summary
C2: Summary - Business Mail 2022 Manifest
A7: Customer Name | C7: Citipost Global | F7: Customer Ref.
A8: Shipment Date | F8: Number of bags/Pallets | H8: 1
B10: Priority | H10: Economy | P10: =ROUND(#REF!,3) -> #REF! | Q10: =ROUND(#REF!,3) -> #REF! | R10: =ROUND(#REF!,3) -> #REF! | S10: =ROUND(#REF!,3) -> #REF! | T10: =ROUND(#REF!,3) -> #REF! | U10: =ROUND(#REF!,3) -> #REF! | V10: =ROUND(#REF!,3) -> #REF! | W10: =ROUND(#REF!,3) -> #REF! | ... Z10: =ROUND(#REF!,3) -> #REF! | AA10: =ROUND(O10,3) -> 0 | AB10: =ROUND(P10,3) -> #REF! | AC10: =ROUND(Q10,3) -> #REF! | AD10: =ROUND(R10,3) -> #REF! | AE10: =ROUND(S10,3) -> #REF! | AF10: =ROUND(T10,3) -> #REF! | AG10: =ROUND(U10,3) -> #REF! | AH10: =ROUND(V10,3) -> #REF! | ... XFD10: =ROUND(XER10,3) -> #REF!
A11: Main Europe | B11: Letters (P) | D11: Boxable(B) | F11: Nonboxable(N) | H11: Letters (P) | J11: Boxable(B) | L11: Nonboxable(N)
A12: Totals | B12: ='Main Europe'!C35 -> 0 | C12: ='Main Europe'!D35 -> 0 | D12: ='Main Europe'!E35 -> 0 | E12: ='Main Europe'!F35 -> 0 | F12: ='Main Europe'!G35 -> 0 | G12: ='Main Europe'!H35 -> 0 | H12: ='Main Europe'!I35 -> 0 | I12: ='Main Europe'!J35 -> 0 | ... M12: ='Main Europe'!N35 -> 0
B14: Priority | H14: Economy
A15: Rest of Europe | B15: Letters (P) | D15: Flats(G) | F15: Packet(E) | H15: Letters (P) | J15: Flats(G) | L15: Packet(E)
A16: Totals | B16: ='Rest of Europe'!C28 -> 0 | C16: ='Rest of Europe'!D28 -> 0 | D16: ='Rest of Europe'!E28 -> 0 | E16: ='Rest of Europe'!F28 -> 0 | F16: ='Rest of Europe'!G28 -> 0 | G16: ='Rest of Europe'!H28 -> 0 | H16: ='Rest of Europe'!I28 -> 0 | I16: ='Rest of Europe'!J28 -> 0 | ... M16: ='Rest of Europe'!N28 -> 0
B18: Priority | H18: Economy
A19: ROW | B19: Letters (P) | D19: Flats(G) | F19: Packet(E) | H19: Letters (P) | J19: Flats(G) | L19: Packet(E)
A20: Totals | B20: =SUM(ROW!B6,ROW!I18,ROW!I33,ROW!I43,'ROW (Continued)'!I14,'ROW (Continued)'!I43) -> 0 | C20: =SUM(ROW!C6,ROW!J18,ROW!J33,ROW!J43,'ROW (Continued)'!J14,'ROW (Continued)'!J43) -> 0 | D20: =SUM(ROW!D6,ROW!K18,ROW!K33,ROW!K43,'ROW (Continued)'!K14,'ROW (Continued)'!K43) -> 0 | E20: =SUM(ROW!E6,ROW!L18,ROW!L33,ROW!L43,'ROW (Continued)'!L14,'ROW (Continued)'!L43) -> 0 | F20: =SUM(ROW!F6,ROW!M18,ROW!M33,ROW!M43,'ROW (Continued)'!M14,'ROW (Continued)'!M43) -> 0 | G20: =SUM(ROW!G6,ROW!N18,ROW!N33,ROW!N43,'ROW (Continued)'!N14,'ROW (Continued)'!N43) -> 0 | H20: =SUM(ROW!B53,ROW!I65,ROW!I80,ROW!I90,'ROW (Continued)'!I58,'ROW (Continued)'!I87) -> 0 | I20: =SUM(ROW!C53,ROW!J65,ROW!J80,ROW!J90,'ROW (Continued)'!J58,'ROW (Continued)'!J87) -> 0 | J20: =SUM(ROW!D53,ROW!K65,ROW!K80,ROW!K90,'ROW (Continued)'!K58,'ROW (Continued)'!K87) -> 0 | K20: =SUM(ROW!E53,ROW!L65,ROW!L80,ROW!L90,'ROW (Continued)'!L58,'ROW (Continued)'!L87) -> 0 | L20: =SUM(ROW!F53,ROW!M65,ROW!M80,ROW!M90,'ROW (Continued)'!M58,'ROW (Continued)'!M87) -> 0 | M20: =SUM(ROW!G53,ROW!N65,ROW!N80,ROW!N90,'ROW (Continued)'!N58,'ROW (Continued)'!N87) -> 0
B22: ='M-Bags'!B84 -> 0-5kg | D22: ='M-Bags'!D84 -> 5-20kg
A23: M-bags Priority | B23: Items | C23: ='M-Bags'!C85 -> Kilos | D23: Items | E23: ='M-Bags'!E85 -> Kilos
A24: Totals | B24: ='M-Bags'!B86 -> 0 | C24: ='M-Bags'!C86 -> 0 | D24: ='M-Bags'!D86 -> 0 | E24: ='M-Bags'!E86 -> 0
B26: ='M-Bags'!B173 -> 0-5kg | D26: ='M-Bags'!D173 -> 5-20kg
A27: M-bags Economy | B27: Items | C27: ='M-Bags'!C174 -> Kilos | D27: Items | E27: ='M-Bags'!E174 -> Kilos | L27: Items | M27: Kilos
A28: Totals | B28: ='M-Bags'!B175 -> 0 | C28: ='M-Bags'!C175 -> 0 | D28: ='M-Bags'!D175 -> 0 | E28: ='M-Bags'!E175 -> 0 | K28: Total | L28: =SUM(B28,D28,D24,B24,B20,D20,F20,H20,J20,L20,L16,J16,H16,F16,D16,B16,B12,D12,F12,H12,J12,L12) -> 0 | M28: =SUM(E28,C28,C24,E24,C20,E20,G20,I20,K20,M20,M16,K16,I16,G16,E16,C16,C12,E12,G12,I12,K12,M12) -> 0
B30: Notes/Comments

Sheet Main Europe
A2: Business Mail 2022 Manifest
B4: Main Europe (EEA +CH)
A5: Service | C5: Priority | I5: Economy
A6: Format | C6: Letters (P) | E6: Boxable(B) | G6: Nonboxable(N) | I6: Letters (P) | K6: Boxable(B) | M6: Nonboxable(N)
A7: Destination | C7: Items | D7: Kilos | E7: Items | F7: Kilos | G7: Items | H7: Kilos | I7: Items | J7: Kilos | K7: Items | L7: Kilos | M7: Items | N7: Kilos
A8: Austria | P8: =ROUND(D8,3) -> 0 | Q8: =ROUND(E8,3) -> 0 | R8: =ROUND(F8,3) -> 0 | S8: =ROUND(G8,3) -> 0 | T8: =ROUND(H8,3) -> 0 | U8: =ROUND(I8,3) -> 0 | V8: =ROUND(J8,3) -> 0 | W8: =ROUND(K8,3) -> 0 | ... XFD8: =ROUND(XER8,3) -> 0
A9: Belgium
A10: Croatia
A11: Czech Rep
A12: Denmark
A13: Estonia
A14: Finland
A15: France
A16: Germany
A17: Greece
A18: Hungary
A19: Iceland
A20: Ireland
... A34: Switzerland
A35: Total | C35: =SUM(C8:C34) -> 0 | D35: =SUM(D8:D34) -> 0 | E35: =SUM(E8:E34) -> 0 | F35: =SUM(F8:F34) -> 0 | G35: =SUM(G8:G34) -> 0 | H35: =SUM(H8:H34) -> 0 | I35: =SUM(I8:I34) -> 0 | J35: =SUM(J8:J34) -> 0 | ... N35: =SUM(N8:N34) -> 0

Sheet Rest of Europe
A2: Business Mail 2022 Manifest
A4: Rest of Europe
A5: Service | C5: Priority | I5: Economy
A6: Format | C6: Letters (P) | E6: Boxable(B) | G6: Nonboxable(N) | I6: Letters (P) | K6: Boxable(B) | M6: Nonboxable(N)
A7: Destination | C7: Items | D7: Kilos | E7: Items | F7: Kilos | G7: Items | H7: Kilos | I7: Items | J7: Kilos | K7: Items | L7: Kilos | M7: Items | N7: Kilos
A8: Albania | P8: =ROUND(D8,3) -> 0 | Q8: =ROUND(E8,3) -> 0 | R8: =ROUND(F8,3) -> 0 | S8: =ROUND(G8,3) -> 0 | T8: =ROUND(H8,3) -> 0 | U8: =ROUND(I8,3) -> 0 | V8: =ROUND(J8,3) -> 0 | W8: =ROUND(K8,3) -> 0 | ... XFD8: =ROUND(XER8,3) -> 0
A9: Armenia
A10: Azerbaijan
A11: Belarus
A12: Bosnia Her.
A13: Bulgaria
A14: Cyprus
A15: Georgia
A16: Kazakhstan
A17: Kyrgyzstan
A18: Macedonia
A19: Malta
A20: Moldova
... A27: Uzbekistan
A28: Total | C28: =SUM(C8:C27) -> 0 | D28: =SUM(D8:D27) -> 0 | E28: =SUM(E8:E27) -> 0 | F28: =SUM(F8:F27) -> 0 | G28: =SUM(G8:G27) -> 0 | H28: =SUM(H8:H27) -> 0 | I28: =SUM(I8:I27) -> 0 | J28: =SUM(J8:J27) -> 0 | ... N28: =SUM(N8:N27) -> 0

Sheet ROW
B1: 2022 Priority Manifest - ROW
B2: Letters (P) | D2: Flats (G) | F2: Packets (E)
A3: North America | B3: Items | C3: Kilos | D3: Items | E3: Kilos | F3: Items | G3: Kilos
A4: Canada
A5: USA
A6: Total | B6: =SUM(B4:B5) -> 0 | C6: =SUM(C4:C5) -> 0 | D6: =SUM(D4:D5) -> 0 | E6: =SUM(E4:E5) -> 0 | F6: =SUM(F4:F5) -> 0 | G6: =SUM(G4:G5) -> 0
B8: Letters (P) | D8: Flats (G) | F8: Packets (E) | I8: Letters (P) | K8: Flats (G) | M8: Packets (E)
A9: C & South America | B9: Items | C9: Kilos | D9: Items | E9: Kilos | F9: Items | G9: Kilos | H9: C&S America (Cont'd) | I9: Items | J9: Kilos | K9: Items | L9: Kilos | M9: Items | N9: Kilos
A10: Antigua & Barbuda | H10: St. Kitts & Nevis
A11: Argentina | H11: St. Lucia
A12: Aruba | H12: St. Vincent
A13: Bahamas | H13: Suriname
A14: Barbados | H14: Trinidad & Tobago
A15: Belize | H15: Turks & Caicos
A16: Bermuda | H16: Uruguay
A17: Bolivia | H17: Venezuela
A18: Brazil | H18: Total | I18: =SUM(I10:I17,B10:B42) -> 0 | J18: =SUM(J10:J17,C10:C42) -> 0 | K18: =SUM(K10:K17,D10:D42) -> 0 | L18: =SUM(L10:L17,E10:E42) -> 0 | M18: =SUM(M10:M17,F10:F42) -> 0 | N18: =SUM(N10:N17,G10:G42) -> 0
A19: Cayman Islands
A20: Chile | I20: Letters (P) | K20: Flats (G) | M20: Packets (E)
A21: Colombia | H21: Middle East | I21: Items | J21: Kilos | K21: Items | L21: Kilos | M21: Items | N21: Kilos
A22: Costa Rica | H22: Bahrain
A23: Cuba | H23: Egypt
A24: Dominica | H24: Iraq
A25: Dominican Republic | H25: Israel
A26: Ecuador | H26: Jordan
A27: El Salvador | H27: Kuwait
A28: French Guiana | H28: Lebanon
A29: Grenada | H29: Oman
A30: Guadeloupe | H30: Qatar
A31: Guatemala | H31: Saudi Arabia
A32: Guyana | H32: UAE
A33: Honduras | H33: Total | I33: =SUM(I22:I32) -> 0 | J33: =SUM(J22:J32) -> 0 | K33: =SUM(K22:K32) -> 0 | L33: =SUM(L22:L32) -> 0 | M33: =SUM(M22:M32) -> 0 | N33: =SUM(N22:N32) -> 0
A34: Jamaica
A35: Martinique | I35: Letters (P) | K35: Flats (G) | M35: Packets (E)
A36: Mexico | H36: Asia | I36: Items | J36: Kilos | K36: Items | L36: Kilos | M36: Items | N36: Kilos
A37: Nicaragua | H37: Afghanistan
A38: Panama | H38: Bangladesh
A39: Paraguay | H39: India
A40: Peru | H40: Nepal
A41: Puerto Rico | H41: Pakistan
...

Sheet ROW (Continued)
A1: Business Mail 2022 Priority Manifest - ROW
B2: Letters (P) | D2: Flats (G) | F2: Packets (E)
A3: Africa | B3: Items | C3: Kilos | D3: Items | E3: Kilos | F3: Items | G3: Kilos | I3: Letters (P) | K3: Flats (G) | M3: Packets (E)
A4: Algeria | H4: Africa (Cont'd) | I4: Items | J4: Kilos | K4: Items | L4: Kilos | M4: Items | N4: Kilos
A5: Angola | H5: Tunisia
A6: Benin | H6: Uganda
A7: Botswana | H7: Algeria
A8: Burkina Faso | H8: Angola
A9: Burundi | H9: Benin
A10: Cameroon | H10: Botswana
A11: Central African Rep. | H11: Burkina Faso
A12: Chad | H12: Zambia
A13: Congo, Dem. Rep. | H13: Zimbabwe
A14: Congo, Rep. of | H14: Total | I14: =SUM(I5:I13,B4:B46) -> 0 | J14: =SUM(J5:J13,C4:C46) -> 0 | K14: =SUM(K5:K13,D4:D46) -> 0 | L14: =SUM(L5:L13,E4:E46) -> 0 | M14: =SUM(M5:M13,F4:F46) -> 0 | N14: =SUM(N5:N13,G4:G46) -> 0
A15: Djibouti
A16: Equatorial Guinea | I16: Letters (P) | K16: Flats (G) | M16: Packets (E)
A17: Eritrea | H17: Far East & Australasia | I17: Items | J17: Kilos | K17: Items | L17: Kilos | M17: Items | N17: Kilos
A18: Ethiopia | H18: American Samoa
A19: Gabon | H19: Australia
A20: Gambia | H20: Brunei Darussalam
A21: Ghana | H21: Cambodia
A22: Guinea | H22: China
A23: Ivory Coast | H23: Fiji
A24: Kenya | H24: French Polynesia
A25: Lesotho | H25: Hong Kong
A26: Liberia | H26: Indonesia
A27: Madagascar | H27: Japan
A28: Malawi | H28: Korea
A29: Maldives | H29: Laos, Rep. of
... A42: South Africa | H42: Vietnam
A43: Sudan | H43: Total | I43: =SUM(I18:I42) -> 0 | J43: =SUM(J18:J42) -> 0 | K43: =SUM(K18:K42) -> 0 | L43: =SUM(L18:L42) -> 0 | M43: =SUM(M18:M42) -> 0 | N43: =SUM(N18:N42) -> 0
A44: Swaziland
A45: Tanzania
A46: Togo
A49: 2022 Economy Manifest - ROW
B50: Letters (P) | D50: Flats (G) | F50: Packets (E)
A51: Africa | B51: Items | C51: Kilos | D51: Items | E51: Kilos | F51: Items | G51: Kilos | I51: Letters (P) | K51: Flats (G) | M51: Packets (E)
A52: Algeria | H52: Africa (Cont'd) | I52: Items | J52: Kilos | K52: Items | L52: Kilos | M52: Items | N52: Kilos
A53: Angola | H53: Algeria
A54: Benin | H54: Angola
...

Sheet M-Bags
B1: 2022 Priority M-Bags Manifest
B3: 0-5kg | D3: 5-20kg | G3: 0-5kg | I3: 5-20kg | K3: Far East | L3: 0-5kg | N3: 5-20kg
A4: W. Europe | B4: item | C4: Kilos | D4: item | E4: Kilos | F4: Rest of Europe | G4: item | H4: Kilos | I4: item | J4: Kilos | K4: & Australasia | L4: item | M4: Kilos | N4: item | O4: Kilos
A5: Austria | F5: Albania | K5: American Samoa
A6: Belgium | F6: Armenia | K6: Australia
A7: Denmark | F7: Azerbaijan | K7: Brunei Darussalam
A8: Finland | F8: Belarus | K8: Cambodia
A9: France | F9: Bosnia-Herzegovina | K9: China
A10: Germany | F10: Bulgaria | K10: Fiji
A11: Greece | F11: Croatia | K11: French Polynesia
A12: Iceland | F12: Cyprus | K12: Hong Kong
A13: Ireland | F13: Czech Republic | K13: Indonesia
A14: Italy | F14: Estonia | K14: Korea
A15: Luxembourg | F15: Georgia | K15: Laos
A16: Netherlands | F16: Hungary | K16: Malaysia
... A21: Switzerland | F21: Macedonia | K21: Singapore
F22: Malta | K22: Taiwan
B23: 0-5kg | D23: 5-20kg | F23: Moldova | K23: Thailand
A24: North America | B24: item | C24: Kilos | D24: item | E24: Kilos | F24: Montenegro | K24: Viet Nam
A25: Canada | F25: Polan*
A26: USA | F26: Romania
F27: Russia
F28: Serbia
B29: 0-5kg | D29: 5-20kg | F29: Slovakia
B30: item | C30: Kilos | D30: item | E30: Kilos | F30: Slovenia
A31: Middle East | F31: Turkey
A32: Bahrain | F32: Ukraine
A33: Egypt | F33: Uzbekistan
A34: Iraq
A35: Israel
A36: Jordan
A37: Kuwait
A38: Lebanon
A39: Oman
A40: Qatar
A41: Saudi Arabia
A42: United Arab Emirates
G46: 0-5kg | I46: 5-20kg | L46: 0-5kg | N46: 5-20kg
B47: 0-5kg | D47: 5-20kg | F47: Africa | G47: item | H47: Kilos | I47: item | J47: Kilos | K47: Central & South America | L47: item | M47: Kilos | N47: item | O47: Kilos
A48: Africa | B48: item | C48: Kilos | D48: item | E48: Kilos | F48: Sierra Leone | K48: Guyana
...
